Workbook

Sheet Adj Close Prices
A1: Date | B1: IVV | C1: ARCC | D1: TSLX | E1: BXSL | F1: JPST | G1: S&P 500
A2: 45076 | B2: 405.21 | C2: 14.23 | D2: 13.69 | E2: 18.6 | F2: 43.48 | G2: 4205.52
A3: 45077 | B3: 402.71 | C3: 14.13 | D3: 13.62 | E3: 18.62 | F3: 43.51 | G3: 4179.83
A4: 45078 | B4: 406.86 | C4: 14.34 | D4: 13.96 | E4: 18.65 | F4: 43.53 | G4: 4221.02
A5: 45079 | B5: 412.66 | C5: 14.39 | D5: 13.95 | E5: 18.87 | F5: 43.52 | G5: 4282.37
A6: 45082 | B6: 411.95 | C6: 14.38 | D6: 14.08 | E6: 18.98 | F6: 43.53 | G6: 4273.79
A7: 45083 | B7: 412.82 | C7: 14.38 | D7: 14.06 | E7: 18.96 | F7: 43.52 | G7: 4283.85
A8: 45084 | B8: 411.46 | C8: 14.35 | D8: 14.15 | E8: 19.03 | F8: 43.52 | G8: 4267.52
A9: 45085 | B9: 413.84 | C9: 14.38 | D9: 14.17 | E9: 18.96 | F9: 43.54 | G9: 4293.93
A10: 45086 | B10: 414.67 | C10: 14.41 | D10: 14.17 | E10: 18.91 | F10: 43.54 | G10: 4298.86
A11: 45089 | B11: 418.43 | C11: 14.36 | D11: 14.3 | E11: 19 | F11: 43.53 | G11: 4338.93
A12: 45090 | B12: 421.17 | C12: 14.36 | D12: 14.34 | E12: 19.2 | F12: 43.53 | G12: 4369.01
A13: 45091 | B13: 421.66 | C13: 14.33 | D13: 14.25 | E13: 19.02 | F13: 43.52 | G13: 4372.59
... A754: 46171 | B754: 760.05 | C754: 18.99 | D754: 17.23 | E754: 23.73 | F754: 50.62 | G754: 7580.05
A756: DAILY RETURNS
A757: Date | B757: IVV | C757: ARCC | D757: TSLX | E757: BXSL | F757: JPST | G757: S&P 500
A758: =A3 | B758: =B3/B2-1 | C758: =C3/C2-1 | D758: =D3/D2-1 | E758: =E3/E2-1 | F758: =F3/F2-1 | G758: =G3/G2-1
A759: =A4 | B759: =B4/B3-1 | C759: =C4/C3-1 | D759: =D4/D3-1 | E759: =E4/E3-1 | F759: =F4/F3-1 | G759: =G4/G3-1
A760: =A5 | B760: =B5/B4-1 | C760: =C5/C4-1 | D760: =D5/D4-1 | E760: =E5/E4-1 | F760: =F5/F4-1 | G760: =G5/G4-1
A761: =A6 | B761: =B6/B5-1 | C761: =C6/C5-1 | D761: =D6/D5-1 | E761: =E6/E5-1 | F761: =F6/F5-1 | G761: =G6/G5-1
A762: =A7 | B762: =B7/B6-1 | C762: =C7/C6-1 | D762: =D7/D6-1 | E762: =E7/E6-1 | F762: =F7/F6-1 | G762: =G7/G6-1
A763: =A8 | B763: =B8/B7-1 | C763: =C8/C7-1 | D763: =D8/D7-1 | E763: =E8/E7-1 | F763: =F8/F7-1 | G763: =G8/G7-1
A764: =A9 | B764: =B9/B8-1 | C764: =C9/C8-1 | D764: =D9/D8-1 | E764: =E9/E8-1 | F764: =F9/F8-1 | G764: =G9/G8-1
A765: =A10 | B765: =B10/B9-1 | C765: =C10/C9-1 | D765: =D10/D9-1 | E765: =E10/E9-1 | F765: =F10/F9-1 | G765: =G10/G9-1
A766: =A11 | B766: =B11/B10-1 | C766: =C11/C10-1 | D766: =D11/D10-1 | E766: =E11/E10-1 | F766: =F11/F10-1 | G766: =G11/G10-1
A767: =A12 | B767: =B12/B11-1 | C767: =C12/C11-1 | D767: =D12/D11-1 | E767: =E12/E11-1 | F767: =F12/F11-1 | G767: =G12/G11-1
A768: =A13 | B768: =B13/B12-1 | C768: =C13/C12-1 | D768: =D13/D12-1 | E768: =E13/E12-1 | F768: =F13/F12-1 | G768: =G13/G12-1
A769: =A14 | B769: =B14/B13-1 | C769: =C14/C13-1 | D769: =D14/D13-1 | E769: =E14/E13-1 | F769: =F14/F13-1 | G769: =G14/G13-1
... A1509: =A754 | B1509: =B754/B753-1 | C1509: =C754/C753-1 | D1509: =D754/D753-1 | E1509: =E754/E753-1 | F1509: =F754/F753-1 | G1509: =G754/G753-1
A1511: RETURN METRICS
A1512: Total Return | B1512: =(B754-B2)/B2 | C1512: =(C754-C2)/C2 | D1512: =(D754-D2)/D2 | E1512: =(E754-E2)/E2 | F1512: =(F754-F2)/F2 | G1512: =(G754-G2)/G2
A1513: CAGR | B1513: =(B754/B2)^(252/(ROWS(B2:B754)-1))-1 | C1513: =(C754/C2)^(252/(ROWS(C2:C754)-1))-1 | D1513: =(D754/D2)^(252/(ROWS(D2:D754)-1))-1 | E1513: =(E754/E2)^(252/(ROWS(E2:E754)-1))-1 | F1513: =(F754/F2)^(252/(ROWS(F2:F754)-1))-1 | G1513: =(G754/G2)^(252/(ROWS(G2:G754)-1))-1
A1514: Annualized Return | B1514: =AVERAGE(B758:B1509)*252 | C1514: =AVERAGE(C758:C1509)*252 | D1514: =AVERAGE(D758:D1509)*252 | E1514: =AVERAGE(E758:E1509)*252 | F1514: =AVERAGE(F758:F1509)*252 | G1514: =AVERAGE(G758:G1509)*252
A1515: Annualized Volatility | B1515: =STDEV(B758:B1509)*SQRT(252) | C1515: =STDEV(C758:C1509)*SQRT(252) | D1515: =STDEV(D758:D1509)*SQRT(252) | E1515: =STDEV(E758:E1509)*SQRT(252) | F1515: =STDEV(F758:F1509)*SQRT(252) | G1515: =STDEV(G758:G1509)*SQRT(252)
A1517: RISK METRICS (95% confidence)
A1518: Max Drawdown * | B1518: -0.18755668 | C1518: -0.19325012 | D1518: -0.27967549 | E1518: -0.24191936 | F1518: -0.0037653587 | G1518: -0.18901913
A1519: VaR 95% Daily | B1519: =-PERCENTILE(B758:B1509,0.05) | C1519: =-PERCENTILE(C758:C1509,0.05) | D1519: =-PERCENTILE(D758:D1509,0.05) | E1519: =-PERCENTILE(E758:E1509,0.05) | F1519: =-PERCENTILE(F758:F1509,0.05) | G1519: =-PERCENTILE(G758:G1509,0.05)
A1520: ES 95% Daily | B1520: =-AVERAGEIF(B758:B1509,"<="&PERCENTILE(B758:B1509,0.05)) | C1520: =-AVERAGEIF(C758:C1509,"<="&PERCENTILE(C758:C1509,0.05)) | D1520: =-AVERAGEIF(D758:D1509,"<="&PERCENTILE(D758:D1509,0.05)) | E1520: =-AVERAGEIF(E758:E1509,"<="&PERCENTILE(E758:E1509,0.05)) | F1520: =-AVERAGEIF(F758:F1509,"<="&PERCENTILE(F758:F1509,0.05)) | G1520: =-AVERAGEIF(G758:G1509,"<="&PERCENTILE(G758:G1509,0.05))
A1522: * Max Drawdown: pre-computed (max peak-to-trough decline). All other metrics use Excel formulas above.
A1524: RISK-ADJUSTED RATIOS
...

Sheet Portfolio
A1: EQUAL-WEIGHT PORTFOLIO ANALYSIS
A2: Tickers: IVV, ARCC, TSLX, BXSL, JPST | Benchmark: S&P 500 | Risk-Free Rate: 4.00%
A4: PORTFOLIO WEIGHTS
A5: Ticker | B5: Weight
A6: IVV | B6: 0.33
A7: ARCC | B7: 0.127
A8: TSLX | B8: 0.12
A9: BXSL | B9: 0.086
A10: JPST | B10: 0.337
A12: PORTFOLIO DAILY RETURNS
A13: Date | B13: Daily Return | C13: Cum. Return
A14: ='Adj Close Prices'!A758 | B14: =0.33000000*'Adj Close Prices'!B758+0.12700000*'Adj Close Prices'!C758+0.12000000*'Adj Close Prices'!D758+0.08600000*'Adj Close Prices'!E758+0.33700000*'Adj Close Prices'!F758 | C14: =1+B14
A15: ='Adj Close Prices'!A759 | B15: =0.33000000*'Adj Close Prices'!B759+0.12700000*'Adj Close Prices'!C759+0.12000000*'Adj Close Prices'!D759+0.08600000*'Adj Close Prices'!E759+0.33700000*'Adj Close Prices'!F759 | C15: =C14*(1+B15)
A16: ='Adj Close Prices'!A760 | B16: =0.33000000*'Adj Close Prices'!B760+0.12700000*'Adj Close Prices'!C760+0.12000000*'Adj Close Prices'!D760+0.08600000*'Adj Close Prices'!E760+0.33700000*'Adj Close Prices'!F760 | C16: =C15*(1+B16)
A17: ='Adj Close Prices'!A761 | B17: =0.33000000*'Adj Close Prices'!B761+0.12700000*'Adj Close Prices'!C761+0.12000000*'Adj Close Prices'!D761+0.08600000*'Adj Close Prices'!E761+0.33700000*'Adj Close Prices'!F761 | C17: =C16*(1+B17)
A18: ='Adj Close Prices'!A762 | B18: =0.33000000*'Adj Close Prices'!B762+0.12700000*'Adj Close Prices'!C762+0.12000000*'Adj Close Prices'!D762+0.08600000*'Adj Close Prices'!E762+0.33700000*'Adj Close Prices'!F762 | C18: =C17*(1+B18)
A19: ='Adj Close Prices'!A763 | B19: =0.33000000*'Adj Close Prices'!B763+0.12700000*'Adj Close Prices'!C763+0.12000000*'Adj Close Prices'!D763+0.08600000*'Adj Close Prices'!E763+0.33700000*'Adj Close Prices'!F763 | C19: =C18*(1+B19)
A20: ='Adj Close Prices'!A764 | B20: =0.33000000*'Adj Close Prices'!B764+0.12700000*'Adj Close Prices'!C764+0.12000000*'Adj Close Prices'!D764+0.08600000*'Adj Close Prices'!E764+0.33700000*'Adj Close Prices'!F764 | C20: =C19*(1+B20)
A21: ='Adj Close Prices'!A765 | B21: =0.33000000*'Adj Close Prices'!B765+0.12700000*'Adj Close Prices'!C765+0.12000000*'Adj Close Prices'!D765+0.08600000*'Adj Close Prices'!E765+0.33700000*'Adj Close Prices'!F765 | C21: =C20*(1+B21)
A22: ='Adj Close Prices'!A766 | B22: =0.33000000*'Adj Close Prices'!B766+0.12700000*'Adj Close Prices'!C766+0.12000000*'Adj Close Prices'!D766+0.08600000*'Adj Close Prices'!E766+0.33700000*'Adj Close Prices'!F766 | C22: =C21*(1+B22)
A23: ='Adj Close Prices'!A767 | B23: =0.33000000*'Adj Close Prices'!B767+0.12700000*'Adj Close Prices'!C767+0.12000000*'Adj Close Prices'!D767+0.08600000*'Adj Close Prices'!E767+0.33700000*'Adj Close Prices'!F767 | C23: =C22*(1+B23)
A24: ='Adj Close Prices'!A768 | B24: =0.33000000*'Adj Close Prices'!B768+0.12700000*'Adj Close Prices'!C768+0.12000000*'Adj Close Prices'!D768+0.08600000*'Adj Close Prices'!E768+0.33700000*'Adj Close Prices'!F768 | C24: =C23*(1+B24)
A25: ='Adj Close Prices'!A769 | B25: =0.33000000*'Adj Close Prices'!B769+0.12700000*'Adj Close Prices'!C769+0.12000000*'Adj Close Prices'!D769+0.08600000*'Adj Close Prices'!E769+0.33700000*'Adj Close Prices'!F769 | C25: =C24*(1+B25)
A26: ='Adj Close Prices'!A770 | B26: =0.33000000*'Adj Close Prices'!B770+0.12700000*'Adj Close Prices'!C770+0.12000000*'Adj Close Prices'!D770+0.08600000*'Adj Close Prices'!E770+0.33700000*'Adj Close Prices'!F770 | C26: =C25*(1+B26)
... A765: ='Adj Close Prices'!A1509 | B765: =0.33000000*'Adj Close Prices'!B1509+0.12700000*'Adj Close Prices'!C1509+0.12000000*'Adj Close Prices'!D1509+0.08600000*'Adj Close Prices'!E1509+0.33700000*'Adj Close Prices'!F1509 | C765: =C764*(1+B765)
A767: RETURN METRICS
A768: Total Return | B768: =C765-1
A769: CAGR | B769: =C765^(252/ROWS(B14:B765))-1
A770: Annualized Return | B770: =AVERAGE(B14:B765)*252
A771: Annualized Volatility | B771: =STDEV(B14:B765)*SQRT(252)
A773: RISK METRICS (95% confidence)
A774: Max Drawdown * | B774: -0.12075503
A775: VaR 95% Daily | B775: =-PERCENTILE(B14:B765,0.05)
A776: ES 95% Daily | B776: =-AVERAGEIF(B14:B765,"<="&PERCENTILE(B14:B765,0.05))
A778: RISK-ADJUSTED RATIOS
A779: Sharpe Ratio | B779: =(AVERAGE(B14:B765)*252-0.04)/(STDEV(B14:B765)*SQRT(252))
A780: Sortino Ratio | B780: =(AVERAGE(B14:B765)*252-0.04)/(SQRT(SUMPRODUCT((((B14:B765)-0.00015873015873015873)*((B14:B765)<0.00015873015873015873))^2)/ROWS(B14:B765))*SQRT(252))
A781: Treynor Ratio | B781: =(AVERAGE(B14:B765)*252-0.04)/B784
A783: RELATIVE METRICS vs S&P 500
A784: Beta | B784: =SLOPE(B14:B765,'Adj Close Prices'!G758:'Adj Close Prices'!G1509)
...
